2018-06-27 13:55:01,716 - root - ERROR - (2003, "Can't connect to MySQL server on '192.168.18.253' (10061)")
Traceback (most recent call last):
  File "C:\projects\WDSeafileAPI\venv\src\bll\Seafile.py", line 19, in get
    r = dal.SeafileInfor.SeafileInfor.select(fileid)
  File "C:\projects\WDSeafileAPI\venv\src\dal\SeafileInfor.py", line 12, in select
    return dbhelper.select(sql)
  File "C:\projects\WDSeafileAPI\venv\src\util\DBHelper.py", line 62, in select
    self.connectdb()
  File "C:\projects\WDSeafileAPI\venv\src\util\DBHelper.py", line 52, in connectdb
    charset='utf8')
  File "C:\Python27\lib\site-packages\MySQLdb\__init__.py", line 81, in Connect
    return Connection(*args, **kwargs)
  File "C:\Python27\lib\site-packages\MySQLdb\connections.py", line 193, in __init__
    super(Connection, self).__init__(*args, **kwargs2)
OperationalError: (2003, "Can't connect to MySQL server on '192.168.18.253' (10061)")
2018-06-27 13:55:01,723 - tornado.access - INFO - 200 GET /SeafileManager/get?fileid=22 (127.0.0.1) 1043.00ms
